2019-11-16 10:10:38,667 DEBUG 55674   ---  [MainThread] - [GET] -> [/cms/product/3] from:127.0.0.1 costs:85.220 ms data:{
	param: {}, 
	body: {}
} 
2019-11-16 10:10:38,946 DEBUG 55674   ---  [MainThread] - [GET] -> [/cms/product/paginate] from:127.0.0.1 costs:90.450 ms data:{
	param: {}, 
	body: {}
} 
2019-11-16 10:36:35,214 DEBUG 58801   ---  [MainThread] - [GET] -> [/cms/product/3] from:127.0.0.1 costs:40.440 ms data:{
	param: {}, 
	body: {}
} 
2019-11-16 10:36:35,320 DEBUG 58801   ---  [MainThread] - [GET] -> [/cms/product/paginate] from:127.0.0.1 costs:76.540 ms data:{
	param: {}, 
	body: {}
} 
2019-11-16 10:36:35,478 DEBUG 58801   ---  [MainThread] - [POST] -> [/cms/product] from:127.0.0.1 costs:118.700 ms data:{
	param: {}, 
	body: {'category_id': 1, 'img_id': 2, 'name': '芹菜', 'price': '1.00', 'stock': 0, 'summary': '芹菜好吃吗', 'theme_id': 1}
} 
2019-11-16 10:46:54,163 DEBUG 59945   ---  [MainThread] - [GET] -> [/cms/product/3] from:127.0.0.1 costs:42.780 ms data:{
	param: {}, 
	body: {}
} 
2019-11-16 10:46:54,248 DEBUG 59945   ---  [MainThread] - [GET] -> [/cms/product/paginate] from:127.0.0.1 costs:68.640 ms data:{
	param: {}, 
	body: {}
} 
2019-11-16 10:46:54,400 DEBUG 59945   ---  [MainThread] - [PUT] -> [/cms/product/hide/3] from:127.0.0.1 costs:104.360 ms data:{
	param: {}, 
	body: {}
} 
2019-11-16 18:31:38,611 ERROR 75068   ---  [MainThread] - Traceback (most recent call last):
  File "/Users/zhaochenxi/.local/share/virtualenvs/snack-api-lin-g_CxUc26/lib/python3.6/site-packages/flask/app.py", line 1813, in full_dispatch_request
    rv = self.dispatch_request()
  File "/Users/zhaochenxi/.local/share/virtualenvs/snack-api-lin-g_CxUc26/lib/python3.6/site-packages/flask/app.py", line 1799, in dispatch_request
    return self.view_functions[rule.endpoint](**req.view_args)
  File "/Users/zhaochenxi/Home/PythonProjects/flask-api/snack-api-lin/app/api/cms/category.py", line 14, in get
    model = Category.get_model_with_img(cid, err_msg='相关产品种类未添加或已隐藏')
  File "/Users/zhaochenxi/Home/PythonProjects/flask-api/snack-api-lin/app/models/base.py", line 86, in get_model_with_img
    ).filter_by(soft=soft).first()
TypeError: 'NoneType' object is not iterable

2019-11-16 18:31:38,630 DEBUG 75068   ---  [MainThread] - [GET] -> [/cms/category/1] from:127.0.0.1 costs:96.780 ms data:{
	param: {}, 
	body: {}
} 
2019-11-16 18:31:39,030 DEBUG 75068   ---  [MainThread] - [GET] -> [/cms/category/all] from:127.0.0.1 costs:13.500 ms data:{
	param: {}, 
	body: {}
} 
2019-11-16 18:31:41,894 DEBUG 75068   ---  [MainThread] - [POST] -> [/cms/category] from:127.0.0.1 costs:2810.760 ms data:{
	param: {}, 
	body: {'description': '蔬菜世界', 'img_id': 2, 'name': '蔬菜'}
} 
2019-11-16 18:31:41,996 DEBUG 75068   ---  [MainThread] - [PUT] -> [/cms/category/1] from:127.0.0.1 costs:46.620 ms data:{
	param: {}, 
	body: {'description': '炒货天堂', 'img_id': 3, 'name': '炒货'}
} 
2019-11-16 18:31:42,068 DEBUG 75068   ---  [MainThread] - [PUT] -> [/cms/category/hide/1] from:127.0.0.1 costs:16.180 ms data:{
	param: {}, 
	body: {}
} 
2019-11-16 18:31:42,138 DEBUG 75068   ---  [MainThread] - [PUT] -> [/cms/category/show/1] from:127.0.0.1 costs:13.850 ms data:{
	param: {}, 
	body: {}
} 
2019-11-16 18:40:15,702 DEBUG 75191   ---  [MainThread] - [GET] -> [/cms/category/1] from:127.0.0.1 costs:41.700 ms data:{
	param: {}, 
	body: {}
} 
2019-11-16 18:40:16,117 DEBUG 75191   ---  [MainThread] - [GET] -> [/cms/category/paginate] from:127.0.0.1 costs:57.110 ms data:{
	param: {}, 
	body: {}
} 
2019-11-16 18:40:16,148 DEBUG 75191   ---  [MainThread] - [POST] -> [/cms/category] from:127.0.0.1 costs:20.940 ms data:{
	param: {}, 
	body: {'description': '蔬菜世界', 'img_id': 2, 'name': '蔬菜'}
} 
2019-11-16 18:40:16,222 DEBUG 75191   ---  [MainThread] - [PUT] -> [/cms/category/1] from:127.0.0.1 costs:30.110 ms data:{
	param: {}, 
	body: {'description': '炒货天堂', 'img_id': 3, 'name': '炒货'}
} 
2019-11-16 18:40:16,268 DEBUG 75191   ---  [MainThread] - [PUT] -> [/cms/category/hide/1] from:127.0.0.1 costs:28.510 ms data:{
	param: {}, 
	body: {}
} 
2019-11-16 18:40:16,330 DEBUG 75191   ---  [MainThread] - [PUT] -> [/cms/category/show/1] from:127.0.0.1 costs:9.380 ms data:{
	param: {}, 
	body: {}
} 
2019-11-16 18:41:32,183 DEBUG 75252   ---  [MainThread] - [GET] -> [/cms/category/1] from:127.0.0.1 costs:53.990 ms data:{
	param: {}, 
	body: {}
} 
2019-11-16 18:41:32,620 DEBUG 75252   ---  [MainThread] - [GET] -> [/cms/category/paginate] from:127.0.0.1 costs:73.590 ms data:{
	param: {}, 
	body: {}
} 
2019-11-16 18:41:32,704 DEBUG 75252   ---  [MainThread] - [POST] -> [/cms/category] from:127.0.0.1 costs:60.200 ms data:{
	param: {}, 
	body: {'description': '蔬菜世界', 'img_id': 2, 'name': '蔬菜'}
} 
2019-11-16 18:41:32,811 DEBUG 75252   ---  [MainThread] - [PUT] -> [/cms/category/1] from:127.0.0.1 costs:76.990 ms data:{
	param: {}, 
	body: {'description': '炒货天堂', 'img_id': 3, 'name': '炒货'}
} 
2019-11-16 18:41:32,892 DEBUG 75252   ---  [MainThread] - [PUT] -> [/cms/category/hide/1] from:127.0.0.1 costs:30.780 ms data:{
	param: {}, 
	body: {}
} 
2019-11-16 18:41:32,973 DEBUG 75252   ---  [MainThread] - [PUT] -> [/cms/category/show/1] from:127.0.0.1 costs:31.830 ms data:{
	param: {}, 
	body: {}
} 
2019-11-16 18:41:37,261 DEBUG 75276   ---  [MainThread] - [GET] -> [/cms/theme/1] from:127.0.0.1 costs:54.980 ms data:{
	param: {}, 
	body: {}
} 
2019-11-16 18:41:37,316 DEBUG 75276   ---  [MainThread] - [GET] -> [/cms/theme/paginate] from:127.0.0.1 costs:43.770 ms data:{
	param: {}, 
	body: {}
} 
2019-11-16 18:41:40,616 DEBUG 75276   ---  [MainThread] - [PUT] -> [/cms/theme/2] from:127.0.0.1 costs:3267.730 ms data:{
	param: {}, 
	body: {'description': '美味水果世界', 'head_img_id': 1, 'name': '水果世界', 'topic_img_id': 1}
} 
2019-11-16 18:41:41,578 DEBUG 75276   ---  [MainThread] - [PUT] -> [/cms/theme/hide/2] from:127.0.0.1 costs:56.020 ms data:{
	param: {}, 
	body: {}
} 
2019-11-16 18:41:41,764 DEBUG 75276   ---  [MainThread] - [PUT] -> [/cms/theme/show/2] from:127.0.0.1 costs:35.590 ms data:{
	param: {}, 
	body: {}
} 
2019-11-16 22:39:45,771 ERROR 79793   ---  [MainThread] - Traceback (most recent call last):
  File "/Users/zhaochenxi/.local/share/virtualenvs/snack-api-lin-g_CxUc26/lib/python3.6/site-packages/flask/app.py", line 1813, in full_dispatch_request
    rv = self.dispatch_request()
  File "/Users/zhaochenxi/.local/share/virtualenvs/snack-api-lin-g_CxUc26/lib/python3.6/site-packages/flask/app.py", line 1799, in dispatch_request
    return self.view_functions[rule.endpoint](**req.view_args)
  File "/Users/zhaochenxi/Home/PythonProjects/flask-api/snack-api-lin/app/api/cms/product.py", line 15, in get
    return jsonify(model)
  File "/Users/zhaochenxi/.local/share/virtualenvs/snack-api-lin-g_CxUc26/lib/python3.6/site-packages/flask/json/__init__.py", line 321, in jsonify
    dumps(data, indent=indent, separators=separators) + '\n',
  File "/Users/zhaochenxi/.local/share/virtualenvs/snack-api-lin-g_CxUc26/lib/python3.6/site-packages/flask/json/__init__.py", line 179, in dumps
    rv = _json.dumps(obj, **kwargs)
  File "/Users/zhaochenxi/anaconda3/lib/python3.6/json/__init__.py", line 238, in dumps
    **kw).encode(obj)
  File "/Users/zhaochenxi/anaconda3/lib/python3.6/json/encoder.py", line 199, in encode
    chunks = self.iterencode(o, _one_shot=True)
  File "/Users/zhaochenxi/anaconda3/lib/python3.6/json/encoder.py", line 257, in iterencode
    return _iterencode(o, 0)
  File "/Users/zhaochenxi/.local/share/virtualenvs/snack-api-lin-g_CxUc26/lib/python3.6/site-packages/lin/core.py", line 369, in default
    return JSONEncoder.default(self, o)
  File "/Users/zhaochenxi/.local/share/virtualenvs/snack-api-lin-g_CxUc26/lib/python3.6/site-packages/lin/core.py", line 369, in default
    return JSONEncoder.default(self, o)
  File "/Users/zhaochenxi/.local/share/virtualenvs/snack-api-lin-g_CxUc26/lib/python3.6/site-packages/lin/core.py", line 369, in default
    return JSONEncoder.default(self, o)
  [Previous line repeated 907 more times]
  File "/Users/zhaochenxi/.local/share/virtualenvs/snack-api-lin-g_CxUc26/lib/python3.6/site-packages/lin/core.py", line 362, in default
    def default(self, o):
RecursionError: maximum recursion depth exceeded while calling a Python object

2019-11-16 22:39:45,775 DEBUG 79793   ---  [MainThread] - [GET] -> [/cms/product/3] from:127.0.0.1 costs:65.830 ms data:{
	param: {}, 
	body: {}
} 
2019-11-16 22:39:50,446 ERROR 79793   ---  [MainThread] - Traceback (most recent call last):
  File "/Users/zhaochenxi/.local/share/virtualenvs/snack-api-lin-g_CxUc26/lib/python3.6/site-packages/flask/app.py", line 1813, in full_dispatch_request
    rv = self.dispatch_request()
  File "/Users/zhaochenxi/.local/share/virtualenvs/snack-api-lin-g_CxUc26/lib/python3.6/site-packages/flask/app.py", line 1799, in dispatch_request
    return self.view_functions[rule.endpoint](**req.view_args)
  File "/Users/zhaochenxi/Home/PythonProjects/flask-api/snack-api-lin/app/api/cms/product.py", line 39, in get_paginate
    return jsonify(models)
  File "/Users/zhaochenxi/.local/share/virtualenvs/snack-api-lin-g_CxUc26/lib/python3.6/site-packages/flask/json/__init__.py", line 321, in jsonify
    dumps(data, indent=indent, separators=separators) + '\n',
  File "/Users/zhaochenxi/.local/share/virtualenvs/snack-api-lin-g_CxUc26/lib/python3.6/site-packages/flask/json/__init__.py", line 179, in dumps
    rv = _json.dumps(obj, **kwargs)
  File "/Users/zhaochenxi/anaconda3/lib/python3.6/json/__init__.py", line 238, in dumps
    **kw).encode(obj)
  File "/Users/zhaochenxi/anaconda3/lib/python3.6/json/encoder.py", line 199, in encode
    chunks = self.iterencode(o, _one_shot=True)
  File "/Users/zhaochenxi/anaconda3/lib/python3.6/json/encoder.py", line 257, in iterencode
    return _iterencode(o, 0)
  File "/Users/zhaochenxi/.local/share/virtualenvs/snack-api-lin-g_CxUc26/lib/python3.6/site-packages/lin/core.py", line 369, in default
    return JSONEncoder.default(self, o)
  File "/Users/zhaochenxi/.local/share/virtualenvs/snack-api-lin-g_CxUc26/lib/python3.6/site-packages/lin/core.py", line 369, in default
    return JSONEncoder.default(self, o)
  File "/Users/zhaochenxi/.local/share/virtualenvs/snack-api-lin-g_CxUc26/lib/python3.6/site-packages/lin/core.py", line 369, in default
    return JSONEncoder.default(self, o)
  [Previous line repeated 905 more times]
  File "/Users/zhaochenxi/.local/share/virtualenvs/snack-api-lin-g_CxUc26/lib/python3.6/site-packages/lin/core.py", line 362, in default
    def default(self, o):
RecursionError: maximum recursion depth exceeded while calling a Python object

2019-11-16 22:39:50,448 DEBUG 79793   ---  [MainThread] - [GET] -> [/cms/product/paginate] from:127.0.0.1 costs:4466.140 ms data:{
	param: {}, 
	body: {}
} 
2019-11-16 22:39:50,512 DEBUG 79793   ---  [MainThread] - [PUT] -> [/cms/product/hide/3] from:127.0.0.1 costs:52.950 ms data:{
	param: {}, 
	body: {}
} 
2019-11-16 23:48:18,331 DEBUG 82603   ---  [MainThread] - [GET] -> [/cms/product/3] from:127.0.0.1 costs:49.590 ms data:{
	param: {}, 
	body: {}
} 
2019-11-16 23:48:18,675 DEBUG 82603   ---  [MainThread] - [GET] -> [/cms/product/paginate] from:127.0.0.1 costs:59.080 ms data:{
	param: {}, 
	body: {}
} 
2019-11-16 23:48:23,366 DEBUG 82603   ---  [MainThread] - [POST] -> [/cms/product] from:127.0.0.1 costs:4656.550 ms data:{
	param: {}, 
	body: {'category_id': 1, 'img_id': 2, 'name': '芹菜', 'price': '1.00', 'stock': 0, 'summary': '芹菜好吃吗', 'theme_id': 1}
} 
2019-11-16 23:49:00,943 DEBUG 82633   ---  [MainThread] - [GET] -> [/cms/product/3] from:127.0.0.1 costs:43.450 ms data:{
	param: {}, 
	body: {}
} 
2019-11-16 23:49:01,357 DEBUG 82633   ---  [MainThread] - [GET] -> [/cms/product/paginate] from:127.0.0.1 costs:34.190 ms data:{
	param: {}, 
	body: {}
} 
2019-11-16 23:49:01,415 DEBUG 82633   ---  [MainThread] - [POST] -> [/cms/product] from:127.0.0.1 costs:9.960 ms data:{
	param: {}, 
	body: {'category_id': 1, 'img_id': 2, 'name': '芹菜1', 'price': '1.01', 'stock': 0, 'summary': '芹菜好吃吗', 'theme_id': 1}
} 
2019-11-16 23:49:27,326 DEBUG 82660   ---  [MainThread] - [GET] -> [/cms/product/3] from:127.0.0.1 costs:33.270 ms data:{
	param: {}, 
	body: {}
} 
2019-11-16 23:49:27,669 DEBUG 82660   ---  [MainThread] - [GET] -> [/cms/product/paginate] from:127.0.0.1 costs:58.860 ms data:{
	param: {}, 
	body: {}
} 
2019-11-16 23:49:27,764 ERROR 82660   ---  [MainThread] - Traceback (most recent call last):
  File "/Users/zhaochenxi/.local/share/virtualenvs/snack-api-lin-g_CxUc26/lib/python3.6/site-packages/sqlalchemy/engine/base.py", line 1193, in _execute_context
    context)
  File "/Users/zhaochenxi/.local/share/virtualenvs/snack-api-lin-g_CxUc26/lib/python3.6/site-packages/sqlalchemy/engine/default.py", line 509, in do_execute
    cursor.execute(statement, parameters)
  File "/Users/zhaochenxi/.local/share/virtualenvs/snack-api-lin-g_CxUc26/lib/python3.6/site-packages/cymysql/cursors.py", line 135, in execute
    self.errorhandler(exc, value)
  File "/Users/zhaochenxi/.local/share/virtualenvs/snack-api-lin-g_CxUc26/lib/python3.6/site-packages/cymysql/cursors.py", line 37, in errorhandler
    self.connection.errorhandler(self, errorclass, errorvalue)
  File "/Users/zhaochenxi/.local/share/virtualenvs/snack-api-lin-g_CxUc26/lib/python3.6/site-packages/cymysql/connections.py", line 117, in errorhandler
    raise errorvalue
  File "/Users/zhaochenxi/.local/share/virtualenvs/snack-api-lin-g_CxUc26/lib/python3.6/site-packages/cymysql/cursors.py", line 130, in execute
    self._query(query)
  File "/Users/zhaochenxi/.local/share/virtualenvs/snack-api-lin-g_CxUc26/lib/python3.6/site-packages/cymysql/cursors.py", line 240, in _query
    conn.query(q)
  File "/Users/zhaochenxi/.local/share/virtualenvs/snack-api-lin-g_CxUc26/lib/python3.6/site-packages/cymysql/connections.py", line 346, in query
    self._result = MySQLResult(self)
  File "/Users/zhaochenxi/.local/share/virtualenvs/snack-api-lin-g_CxUc26/lib/python3.6/site-packages/cymysql/packet.py", line 270, in __init__
    self.first_packet = MysqlPacket(self.connection)
  File "/Users/zhaochenxi/.local/share/virtualenvs/snack-api-lin-g_CxUc26/lib/python3.6/site-packages/cymysql/packet.py", line 66, in __init__
    raise_mysql_exception(self.__data)
  File "/Users/zhaochenxi/.local/share/virtualenvs/snack-api-lin-g_CxUc26/lib/python3.6/site-packages/cymysql/err.py", line 149, in raise_mysql_exception
    _check_mysql_exception(errinfo)
  File "/Users/zhaochenxi/.local/share/virtualenvs/snack-api-lin-g_CxUc26/lib/python3.6/site-packages/cymysql/err.py", line 141, in _check_mysql_exception
    raise errorclass(errno, errorvalue)
cymysql.err.IntegrityError: (1048, "Column 'price' cannot be null")

The above exception was the direct cause of the following exception:

Traceback (most recent call last):
  File "/Users/zhaochenxi/.local/share/virtualenvs/snack-api-lin-g_CxUc26/lib/python3.6/site-packages/flask/app.py", line 1813, in full_dispatch_request
    rv = self.dispatch_request()
  File "/Users/zhaochenxi/.local/share/virtualenvs/snack-api-lin-g_CxUc26/lib/python3.6/site-packages/flask/app.py", line 1799, in dispatch_request
    return self.view_functions[rule.endpoint](**req.view_args)
  File "/Users/zhaochenxi/Home/PythonProjects/flask-api/snack-api-lin/app/api/cms/product.py", line 51, in create
    Product.add_model(form.data, err_msg='相关商品已存在')
  File "/Users/zhaochenxi/Home/PythonProjects/flask-api/snack-api-lin/app/models/base.py", line 167, in add_model
    cls.create(**data, commit=True)
  File "/Users/zhaochenxi/.local/share/virtualenvs/snack-api-lin-g_CxUc26/lib/python3.6/site-packages/lin/interface.py", line 149, in create
    db.session.commit()
  File "/Users/zhaochenxi/.local/share/virtualenvs/snack-api-lin-g_CxUc26/lib/python3.6/site-packages/sqlalchemy/orm/scoping.py", line 153, in do
    return getattr(self.registry(), name)(*args, **kwargs)
  File "/Users/zhaochenxi/.local/share/virtualenvs/snack-api-lin-g_CxUc26/lib/python3.6/site-packages/sqlalchemy/orm/session.py", line 943, in commit
    self.transaction.commit()
  File "/Users/zhaochenxi/.local/share/virtualenvs/snack-api-lin-g_CxUc26/lib/python3.6/site-packages/sqlalchemy/orm/session.py", line 467, in commit
    self._prepare_impl()
  File "/Users/zhaochenxi/.local/share/virtualenvs/snack-api-lin-g_CxUc26/lib/python3.6/site-packages/sqlalchemy/orm/session.py", line 447, in _prepare_impl
    self.session.flush()
  File "/Users/zhaochenxi/.local/share/virtualenvs/snack-api-lin-g_CxUc26/lib/python3.6/site-packages/sqlalchemy/orm/session.py", line 2254, in flush
    self._flush(objects)
  File "/Users/zhaochenxi/.local/share/virtualenvs/snack-api-lin-g_CxUc26/lib/python3.6/site-packages/sqlalchemy/orm/session.py", line 2380, in _flush
    transaction.rollback(_capture_exception=True)
  File "/Users/zhaochenxi/.local/share/virtualenvs/snack-api-lin-g_CxUc26/lib/python3.6/site-packages/sqlalchemy/util/langhelpers.py", line 66, in __exit__
    compat.reraise(exc_type, exc_value, exc_tb)
  File "/Users/zhaochenxi/.local/share/virtualenvs/snack-api-lin-g_CxUc26/lib/python3.6/site-packages/sqlalchemy/util/compat.py", line 249, in reraise
    raise value
  File "/Users/zhaochenxi/.local/share/virtualenvs/snack-api-lin-g_CxUc26/lib/python3.6/site-packages/sqlalchemy/orm/session.py", line 2344, in _flush
    flush_context.execute()
  File "/Users/zhaochenxi/.local/share/virtualenvs/snack-api-lin-g_CxUc26/lib/python3.6/site-packages/sqlalchemy/orm/unitofwork.py", line 391, in execute
    rec.execute(self)
  File "/Users/zhaochenxi/.local/share/virtualenvs/snack-api-lin-g_CxUc26/lib/python3.6/site-packages/sqlalchemy/orm/unitofwork.py", line 556, in execute
    uow
  File "/Users/zhaochenxi/.local/share/virtualenvs/snack-api-lin-g_CxUc26/lib/python3.6/site-packages/sqlalchemy/orm/persistence.py", line 181, in save_obj
    mapper, table, insert)
  File "/Users/zhaochenxi/.local/share/virtualenvs/snack-api-lin-g_CxUc26/lib/python3.6/site-packages/sqlalchemy/orm/persistence.py", line 866, in _emit_insert_statements
    execute(statement, params)
  File "/Users/zhaochenxi/.local/share/virtualenvs/snack-api-lin-g_CxUc26/lib/python3.6/site-packages/sqlalchemy/engine/base.py", line 948, in execute
    return meth(self, multiparams, params)
  File "/Users/zhaochenxi/.local/share/virtualenvs/snack-api-lin-g_CxUc26/lib/python3.6/site-packages/sqlalchemy/sql/elements.py", line 269, in _execute_on_connection
    return connection._execute_clauseelement(self, multiparams, params)
  File "/Users/zhaochenxi/.local/share/virtualenvs/snack-api-lin-g_CxUc26/lib/python3.6/site-packages/sqlalchemy/engine/base.py", line 1060, in _execute_clauseelement
    compiled_sql, distilled_params
  File "/Users/zhaochenxi/.local/share/virtualenvs/snack-api-lin-g_CxUc26/lib/python3.6/site-packages/sqlalchemy/engine/base.py", line 1200, in _execute_context
    context)
  File "/Users/zhaochenxi/.local/share/virtualenvs/snack-api-lin-g_CxUc26/lib/python3.6/site-packages/sqlalchemy/engine/base.py", line 1413, in _handle_dbapi_exception
    exc_info
  File "/Users/zhaochenxi/.local/share/virtualenvs/snack-api-lin-g_CxUc26/lib/python3.6/site-packages/sqlalchemy/util/compat.py", line 265, in raise_from_cause
    reraise(type(exception), exception, tb=exc_tb, cause=cause)
  File "/Users/zhaochenxi/.local/share/virtualenvs/snack-api-lin-g_CxUc26/lib/python3.6/site-packages/sqlalchemy/util/compat.py", line 248, in reraise
    raise value.with_traceback(tb)
  File "/Users/zhaochenxi/.local/share/virtualenvs/snack-api-lin-g_CxUc26/lib/python3.6/site-packages/sqlalchemy/engine/base.py", line 1193, in _execute_context
    context)
  File "/Users/zhaochenxi/.local/share/virtualenvs/snack-api-lin-g_CxUc26/lib/python3.6/site-packages/sqlalchemy/engine/default.py", line 509, in do_execute
    cursor.execute(statement, parameters)
  File "/Users/zhaochenxi/.local/share/virtualenvs/snack-api-lin-g_CxUc26/lib/python3.6/site-packages/cymysql/cursors.py", line 135, in execute
    self.errorhandler(exc, value)
  File "/Users/zhaochenxi/.local/share/virtualenvs/snack-api-lin-g_CxUc26/lib/python3.6/site-packages/cymysql/cursors.py", line 37, in errorhandler
    self.connection.errorhandler(self, errorclass, errorvalue)
  File "/Users/zhaochenxi/.local/share/virtualenvs/snack-api-lin-g_CxUc26/lib/python3.6/site-packages/cymysql/connections.py", line 117, in errorhandler
    raise errorvalue
  File "/Users/zhaochenxi/.local/share/virtualenvs/snack-api-lin-g_CxUc26/lib/python3.6/site-packages/cymysql/cursors.py", line 130, in execute
    self._query(query)
  File "/Users/zhaochenxi/.local/share/virtualenvs/snack-api-lin-g_CxUc26/lib/python3.6/site-packages/cymysql/cursors.py", line 240, in _query
    conn.query(q)
  File "/Users/zhaochenxi/.local/share/virtualenvs/snack-api-lin-g_CxUc26/lib/python3.6/site-packages/cymysql/connections.py", line 346, in query
    self._result = MySQLResult(self)
  File "/Users/zhaochenxi/.local/share/virtualenvs/snack-api-lin-g_CxUc26/lib/python3.6/site-packages/cymysql/packet.py", line 270, in __init__
    self.first_packet = MysqlPacket(self.connection)
  File "/Users/zhaochenxi/.local/share/virtualenvs/snack-api-lin-g_CxUc26/lib/python3.6/site-packages/cymysql/packet.py", line 66, in __init__
    raise_mysql_exception(self.__data)
  File "/Users/zhaochenxi/.local/share/virtualenvs/snack-api-lin-g_CxUc26/lib/python3.6/site-packages/cymysql/err.py", line 149, in raise_mysql_exception
    _check_mysql_exception(errinfo)
  File "/Users/zhaochenxi/.local/share/virtualenvs/snack-api-lin-g_CxUc26/lib/python3.6/site-packages/cymysql/err.py", line 141, in _check_mysql_exception
    raise errorclass(errno, errorvalue)
sqlalchemy.exc.IntegrityError: (cymysql.err.IntegrityError) (1048, "Column 'price' cannot be null") [SQL: 'INSERT INTO product (create_time, update_time, delete_time, name, price, stock, summary, category_id, theme_id, img_id) VALUES (%s, %s, %s, %s, %s, %s, %s, %s, %s, %s)'] [parameters: (datetime.datetime(2019, 11, 16, 23, 49, 27, 725610), datetime.datetime(2019, 11, 16, 23, 49, 27, 725639), None, '芹菜1', None, 0, '芹菜好吃吗', 1, 1, 2)] (Background on this error at: http://sqlalche.me/e/gkpj)

2019-11-16 23:49:27,767 DEBUG 82660   ---  [MainThread] - [POST] -> [/cms/product] from:127.0.0.1 costs:81.930 ms data:{
	param: {}, 
	body: {'category_id': 1, 'img_id': 2, 'name': '芹菜1', 'price_str': '1.01', 'stock': 0, 'summary': '芹菜好吃吗', 'theme_id': 1}
} 
2019-11-16 23:50:35,313 DEBUG 82686   ---  [MainThread] - [GET] -> [/cms/product/3] from:127.0.0.1 costs:34.660 ms data:{
	param: {}, 
	body: {}
} 
2019-11-16 23:50:35,691 DEBUG 82686   ---  [MainThread] - [GET] -> [/cms/product/paginate] from:127.0.0.1 costs:47.000 ms data:{
	param: {}, 
	body: {}
} 
2019-11-16 23:50:46,716 ERROR 82686   ---  [MainThread] - Traceback (most recent call last):
  File "/Users/zhaochenxi/.local/share/virtualenvs/snack-api-lin-g_CxUc26/lib/python3.6/site-packages/sqlalchemy/engine/base.py", line 1193, in _execute_context
    context)
  File "/Users/zhaochenxi/.local/share/virtualenvs/snack-api-lin-g_CxUc26/lib/python3.6/site-packages/sqlalchemy/engine/default.py", line 509, in do_execute
    cursor.execute(statement, parameters)
  File "/Users/zhaochenxi/.local/share/virtualenvs/snack-api-lin-g_CxUc26/lib/python3.6/site-packages/cymysql/cursors.py", line 135, in execute
    self.errorhandler(exc, value)
  File "/Users/zhaochenxi/.local/share/virtualenvs/snack-api-lin-g_CxUc26/lib/python3.6/site-packages/cymysql/cursors.py", line 37, in errorhandler
    self.connection.errorhandler(self, errorclass, errorvalue)
  File "/Users/zhaochenxi/.local/share/virtualenvs/snack-api-lin-g_CxUc26/lib/python3.6/site-packages/cymysql/connections.py", line 117, in errorhandler
    raise errorvalue
  File "/Users/zhaochenxi/.local/share/virtualenvs/snack-api-lin-g_CxUc26/lib/python3.6/site-packages/cymysql/cursors.py", line 130, in execute
    self._query(query)
  File "/Users/zhaochenxi/.local/share/virtualenvs/snack-api-lin-g_CxUc26/lib/python3.6/site-packages/cymysql/cursors.py", line 240, in _query
    conn.query(q)
  File "/Users/zhaochenxi/.local/share/virtualenvs/snack-api-lin-g_CxUc26/lib/python3.6/site-packages/cymysql/connections.py", line 346, in query
    self._result = MySQLResult(self)
  File "/Users/zhaochenxi/.local/share/virtualenvs/snack-api-lin-g_CxUc26/lib/python3.6/site-packages/cymysql/packet.py", line 270, in __init__
    self.first_packet = MysqlPacket(self.connection)
  File "/Users/zhaochenxi/.local/share/virtualenvs/snack-api-lin-g_CxUc26/lib/python3.6/site-packages/cymysql/packet.py", line 66, in __init__
    raise_mysql_exception(self.__data)
  File "/Users/zhaochenxi/.local/share/virtualenvs/snack-api-lin-g_CxUc26/lib/python3.6/site-packages/cymysql/err.py", line 149, in raise_mysql_exception
    _check_mysql_exception(errinfo)
  File "/Users/zhaochenxi/.local/share/virtualenvs/snack-api-lin-g_CxUc26/lib/python3.6/site-packages/cymysql/err.py", line 141, in _check_mysql_exception
    raise errorclass(errno, errorvalue)
cymysql.err.IntegrityError: (1048, "Column 'price' cannot be null")

The above exception was the direct cause of the following exception:

Traceback (most recent call last):
  File "/Users/zhaochenxi/.local/share/virtualenvs/snack-api-lin-g_CxUc26/lib/python3.6/site-packages/flask/app.py", line 1813, in full_dispatch_request
    rv = self.dispatch_request()
  File "/Users/zhaochenxi/.local/share/virtualenvs/snack-api-lin-g_CxUc26/lib/python3.6/site-packages/flask/app.py", line 1799, in dispatch_request
    return self.view_functions[rule.endpoint](**req.view_args)
  File "/Users/zhaochenxi/Home/PythonProjects/flask-api/snack-api-lin/app/api/cms/product.py", line 51, in create
    Product.add_model(form.data, err_msg='相关商品已存在')
  File "/Users/zhaochenxi/Home/PythonProjects/flask-api/snack-api-lin/app/models/base.py", line 167, in add_model
    cls.create(**data, commit=True)
  File "/Users/zhaochenxi/.local/share/virtualenvs/snack-api-lin-g_CxUc26/lib/python3.6/site-packages/lin/interface.py", line 149, in create
    db.session.commit()
  File "/Users/zhaochenxi/.local/share/virtualenvs/snack-api-lin-g_CxUc26/lib/python3.6/site-packages/sqlalchemy/orm/scoping.py", line 153, in do
    return getattr(self.registry(), name)(*args, **kwargs)
  File "/Users/zhaochenxi/.local/share/virtualenvs/snack-api-lin-g_CxUc26/lib/python3.6/site-packages/sqlalchemy/orm/session.py", line 943, in commit
    self.transaction.commit()
  File "/Users/zhaochenxi/.local/share/virtualenvs/snack-api-lin-g_CxUc26/lib/python3.6/site-packages/sqlalchemy/orm/session.py", line 467, in commit
    self._prepare_impl()
  File "/Users/zhaochenxi/.local/share/virtualenvs/snack-api-lin-g_CxUc26/lib/python3.6/site-packages/sqlalchemy/orm/session.py", line 447, in _prepare_impl
    self.session.flush()
  File "/Users/zhaochenxi/.local/share/virtualenvs/snack-api-lin-g_CxUc26/lib/python3.6/site-packages/sqlalchemy/orm/session.py", line 2254, in flush
    self._flush(objects)
  File "/Users/zhaochenxi/.local/share/virtualenvs/snack-api-lin-g_CxUc26/lib/python3.6/site-packages/sqlalchemy/orm/session.py", line 2380, in _flush
    transaction.rollback(_capture_exception=True)
  File "/Users/zhaochenxi/.local/share/virtualenvs/snack-api-lin-g_CxUc26/lib/python3.6/site-packages/sqlalchemy/util/langhelpers.py", line 66, in __exit__
    compat.reraise(exc_type, exc_value, exc_tb)
  File "/Users/zhaochenxi/.local/share/virtualenvs/snack-api-lin-g_CxUc26/lib/python3.6/site-packages/sqlalchemy/util/compat.py", line 249, in reraise
    raise value
  File "/Users/zhaochenxi/.local/share/virtualenvs/snack-api-lin-g_CxUc26/lib/python3.6/site-packages/sqlalchemy/orm/session.py", line 2344, in _flush
    flush_context.execute()
  File "/Users/zhaochenxi/.local/share/virtualenvs/snack-api-lin-g_CxUc26/lib/python3.6/site-packages/sqlalchemy/orm/unitofwork.py", line 391, in execute
    rec.execute(self)
  File "/Users/zhaochenxi/.local/share/virtualenvs/snack-api-lin-g_CxUc26/lib/python3.6/site-packages/sqlalchemy/orm/unitofwork.py", line 556, in execute
    uow
  File "/Users/zhaochenxi/.local/share/virtualenvs/snack-api-lin-g_CxUc26/lib/python3.6/site-packages/sqlalchemy/orm/persistence.py", line 181, in save_obj
    mapper, table, insert)
  File "/Users/zhaochenxi/.local/share/virtualenvs/snack-api-lin-g_CxUc26/lib/python3.6/site-packages/sqlalchemy/orm/persistence.py", line 866, in _emit_insert_statements
    execute(statement, params)
  File "/Users/zhaochenxi/.local/share/virtualenvs/snack-api-lin-g_CxUc26/lib/python3.6/site-packages/sqlalchemy/engine/base.py", line 948, in execute
    return meth(self, multiparams, params)
  File "/Users/zhaochenxi/.local/share/virtualenvs/snack-api-lin-g_CxUc26/lib/python3.6/site-packages/sqlalchemy/sql/elements.py", line 269, in _execute_on_connection
    return connection._execute_clauseelement(self, multiparams, params)
  File "/Users/zhaochenxi/.local/share/virtualenvs/snack-api-lin-g_CxUc26/lib/python3.6/site-packages/sqlalchemy/engine/base.py", line 1060, in _execute_clauseelement
    compiled_sql, distilled_params
  File "/Users/zhaochenxi/.local/share/virtualenvs/snack-api-lin-g_CxUc26/lib/python3.6/site-packages/sqlalchemy/engine/base.py", line 1200, in _execute_context
    context)
  File "/Users/zhaochenxi/.local/share/virtualenvs/snack-api-lin-g_CxUc26/lib/python3.6/site-packages/sqlalchemy/engine/base.py", line 1413, in _handle_dbapi_exception
    exc_info
  File "/Users/zhaochenxi/.local/share/virtualenvs/snack-api-lin-g_CxUc26/lib/python3.6/site-packages/sqlalchemy/util/compat.py", line 265, in raise_from_cause
    reraise(type(exception), exception, tb=exc_tb, cause=cause)
  File "/Users/zhaochenxi/.local/share/virtualenvs/snack-api-lin-g_CxUc26/lib/python3.6/site-packages/sqlalchemy/util/compat.py", line 248, in reraise
    raise value.with_traceback(tb)
  File "/Users/zhaochenxi/.local/share/virtualenvs/snack-api-lin-g_CxUc26/lib/python3.6/site-packages/sqlalchemy/engine/base.py", line 1193, in _execute_context
    context)
  File "/Users/zhaochenxi/.local/share/virtualenvs/snack-api-lin-g_CxUc26/lib/python3.6/site-packages/sqlalchemy/engine/default.py", line 509, in do_execute
    cursor.execute(statement, parameters)
  File "/Users/zhaochenxi/.local/share/virtualenvs/snack-api-lin-g_CxUc26/lib/python3.6/site-packages/cymysql/cursors.py", line 135, in execute
    self.errorhandler(exc, value)
  File "/Users/zhaochenxi/.local/share/virtualenvs/snack-api-lin-g_CxUc26/lib/python3.6/site-packages/cymysql/cursors.py", line 37, in errorhandler
    self.connection.errorhandler(self, errorclass, errorvalue)
  File "/Users/zhaochenxi/.local/share/virtualenvs/snack-api-lin-g_CxUc26/lib/python3.6/site-packages/cymysql/connections.py", line 117, in errorhandler
    raise errorvalue
  File "/Users/zhaochenxi/.local/share/virtualenvs/snack-api-lin-g_CxUc26/lib/python3.6/site-packages/cymysql/cursors.py", line 130, in execute
    self._query(query)
  File "/Users/zhaochenxi/.local/share/virtualenvs/snack-api-lin-g_CxUc26/lib/python3.6/site-packages/cymysql/cursors.py", line 240, in _query
    conn.query(q)
  File "/Users/zhaochenxi/.local/share/virtualenvs/snack-api-lin-g_CxUc26/lib/python3.6/site-packages/cymysql/connections.py", line 346, in query
    self._result = MySQLResult(self)
  File "/Users/zhaochenxi/.local/share/virtualenvs/snack-api-lin-g_CxUc26/lib/python3.6/site-packages/cymysql/packet.py", line 270, in __init__
    self.first_packet = MysqlPacket(self.connection)
  File "/Users/zhaochenxi/.local/share/virtualenvs/snack-api-lin-g_CxUc26/lib/python3.6/site-packages/cymysql/packet.py", line 66, in __init__
    raise_mysql_exception(self.__data)
  File "/Users/zhaochenxi/.local/share/virtualenvs/snack-api-lin-g_CxUc26/lib/python3.6/site-packages/cymysql/err.py", line 149, in raise_mysql_exception
    _check_mysql_exception(errinfo)
  File "/Users/zhaochenxi/.local/share/virtualenvs/snack-api-lin-g_CxUc26/lib/python3.6/site-packages/cymysql/err.py", line 141, in _check_mysql_exception
    raise errorclass(errno, errorvalue)
sqlalchemy.exc.IntegrityError: (cymysql.err.IntegrityError) (1048, "Column 'price' cannot be null") [SQL: 'INSERT INTO product (create_time, update_time, delete_time, name, price, stock, summary, category_id, theme_id, img_id) VALUES (%s, %s, %s, %s, %s, %s, %s, %s, %s, %s)'] [parameters: (datetime.datetime(2019, 11, 16, 23, 50, 46, 674245), datetime.datetime(2019, 11, 16, 23, 50, 46, 674263), None, '芹菜1', None, 0, '芹菜好吃吗', 1, 1, 2)] (Background on this error at: http://sqlalche.me/e/gkpj)

2019-11-16 23:50:46,719 DEBUG 82686   ---  [MainThread] - [POST] -> [/cms/product] from:127.0.0.1 costs:10999.400 ms data:{
	param: {}, 
	body: {'category_id': 1, 'img_id': 2, 'name': '芹菜1', 'price_str': '1.01', 'stock': 0, 'summary': '芹菜好吃吗', 'theme_id': 1}
} 
2019-11-16 23:51:48,628 DEBUG 82714   ---  [MainThread] - [GET] -> [/cms/product/3] from:127.0.0.1 costs:36.070 ms data:{
	param: {}, 
	body: {}
} 
2019-11-16 23:51:48,983 DEBUG 82714   ---  [MainThread] - [GET] -> [/cms/product/paginate] from:127.0.0.1 costs:38.420 ms data:{
	param: {}, 
	body: {}
} 
2019-11-16 23:51:57,108 ERROR 82714   ---  [MainThread] - Traceback (most recent call last):
  File "/Users/zhaochenxi/.local/share/virtualenvs/snack-api-lin-g_CxUc26/lib/python3.6/site-packages/sqlalchemy/engine/base.py", line 1193, in _execute_context
    context)
  File "/Users/zhaochenxi/.local/share/virtualenvs/snack-api-lin-g_CxUc26/lib/python3.6/site-packages/sqlalchemy/engine/default.py", line 509, in do_execute
    cursor.execute(statement, parameters)
  File "/Users/zhaochenxi/.local/share/virtualenvs/snack-api-lin-g_CxUc26/lib/python3.6/site-packages/cymysql/cursors.py", line 135, in execute
    self.errorhandler(exc, value)
  File "/Users/zhaochenxi/.local/share/virtualenvs/snack-api-lin-g_CxUc26/lib/python3.6/site-packages/cymysql/cursors.py", line 37, in errorhandler
    self.connection.errorhandler(self, errorclass, errorvalue)
  File "/Users/zhaochenxi/.local/share/virtualenvs/snack-api-lin-g_CxUc26/lib/python3.6/site-packages/cymysql/connections.py", line 117, in errorhandler
    raise errorvalue
  File "/Users/zhaochenxi/.local/share/virtualenvs/snack-api-lin-g_CxUc26/lib/python3.6/site-packages/cymysql/cursors.py", line 130, in execute
    self._query(query)
  File "/Users/zhaochenxi/.local/share/virtualenvs/snack-api-lin-g_CxUc26/lib/python3.6/site-packages/cymysql/cursors.py", line 240, in _query
    conn.query(q)
  File "/Users/zhaochenxi/.local/share/virtualenvs/snack-api-lin-g_CxUc26/lib/python3.6/site-packages/cymysql/connections.py", line 346, in query
    self._result = MySQLResult(self)
  File "/Users/zhaochenxi/.local/share/virtualenvs/snack-api-lin-g_CxUc26/lib/python3.6/site-packages/cymysql/packet.py", line 270, in __init__
    self.first_packet = MysqlPacket(self.connection)
  File "/Users/zhaochenxi/.local/share/virtualenvs/snack-api-lin-g_CxUc26/lib/python3.6/site-packages/cymysql/packet.py", line 66, in __init__
    raise_mysql_exception(self.__data)
  File "/Users/zhaochenxi/.local/share/virtualenvs/snack-api-lin-g_CxUc26/lib/python3.6/site-packages/cymysql/err.py", line 149, in raise_mysql_exception
    _check_mysql_exception(errinfo)
  File "/Users/zhaochenxi/.local/share/virtualenvs/snack-api-lin-g_CxUc26/lib/python3.6/site-packages/cymysql/err.py", line 141, in _check_mysql_exception
    raise errorclass(errno, errorvalue)
cymysql.err.IntegrityError: (1048, "Column 'price' cannot be null")

The above exception was the direct cause of the following exception:

Traceback (most recent call last):
  File "/Users/zhaochenxi/.local/share/virtualenvs/snack-api-lin-g_CxUc26/lib/python3.6/site-packages/flask/app.py", line 1813, in full_dispatch_request
    rv = self.dispatch_request()
  File "/Users/zhaochenxi/.local/share/virtualenvs/snack-api-lin-g_CxUc26/lib/python3.6/site-packages/flask/app.py", line 1799, in dispatch_request
    return self.view_functions[rule.endpoint](**req.view_args)
  File "/Users/zhaochenxi/Home/PythonProjects/flask-api/snack-api-lin/app/api/cms/product.py", line 51, in create
    Product.add_model(form.data, err_msg='相关商品已存在')
  File "/Users/zhaochenxi/Home/PythonProjects/flask-api/snack-api-lin/app/models/base.py", line 167, in add_model
    cls.create(**data, commit=True)
  File "/Users/zhaochenxi/.local/share/virtualenvs/snack-api-lin-g_CxUc26/lib/python3.6/site-packages/lin/interface.py", line 149, in create
    db.session.commit()
  File "/Users/zhaochenxi/.local/share/virtualenvs/snack-api-lin-g_CxUc26/lib/python3.6/site-packages/sqlalchemy/orm/scoping.py", line 153, in do
    return getattr(self.registry(), name)(*args, **kwargs)
  File "/Users/zhaochenxi/.local/share/virtualenvs/snack-api-lin-g_CxUc26/lib/python3.6/site-packages/sqlalchemy/orm/session.py", line 943, in commit
    self.transaction.commit()
  File "/Users/zhaochenxi/.local/share/virtualenvs/snack-api-lin-g_CxUc26/lib/python3.6/site-packages/sqlalchemy/orm/session.py", line 467, in commit
    self._prepare_impl()
  File "/Users/zhaochenxi/.local/share/virtualenvs/snack-api-lin-g_CxUc26/lib/python3.6/site-packages/sqlalchemy/orm/session.py", line 447, in _prepare_impl
    self.session.flush()
  File "/Users/zhaochenxi/.local/share/virtualenvs/snack-api-lin-g_CxUc26/lib/python3.6/site-packages/sqlalchemy/orm/session.py", line 2254, in flush
    self._flush(objects)
  File "/Users/zhaochenxi/.local/share/virtualenvs/snack-api-lin-g_CxUc26/lib/python3.6/site-packages/sqlalchemy/orm/session.py", line 2380, in _flush
    transaction.rollback(_capture_exception=True)
  File "/Users/zhaochenxi/.local/share/virtualenvs/snack-api-lin-g_CxUc26/lib/python3.6/site-packages/sqlalchemy/util/langhelpers.py", line 66, in __exit__
    compat.reraise(exc_type, exc_value, exc_tb)
  File "/Users/zhaochenxi/.local/share/virtualenvs/snack-api-lin-g_CxUc26/lib/python3.6/site-packages/sqlalchemy/util/compat.py", line 249, in reraise
    raise value
  File "/Users/zhaochenxi/.local/share/virtualenvs/snack-api-lin-g_CxUc26/lib/python3.6/site-packages/sqlalchemy/orm/session.py", line 2344, in _flush
    flush_context.execute()
  File "/Users/zhaochenxi/.local/share/virtualenvs/snack-api-lin-g_CxUc26/lib/python3.6/site-packages/sqlalchemy/orm/unitofwork.py", line 391, in execute
    rec.execute(self)
  File "/Users/zhaochenxi/.local/share/virtualenvs/snack-api-lin-g_CxUc26/lib/python3.6/site-packages/sqlalchemy/orm/unitofwork.py", line 556, in execute
    uow
  File "/Users/zhaochenxi/.local/share/virtualenvs/snack-api-lin-g_CxUc26/lib/python3.6/site-packages/sqlalchemy/orm/persistence.py", line 181, in save_obj
    mapper, table, insert)
  File "/Users/zhaochenxi/.local/share/virtualenvs/snack-api-lin-g_CxUc26/lib/python3.6/site-packages/sqlalchemy/orm/persistence.py", line 866, in _emit_insert_statements
    execute(statement, params)
  File "/Users/zhaochenxi/.local/share/virtualenvs/snack-api-lin-g_CxUc26/lib/python3.6/site-packages/sqlalchemy/engine/base.py", line 948, in execute
    return meth(self, multiparams, params)
  File "/Users/zhaochenxi/.local/share/virtualenvs/snack-api-lin-g_CxUc26/lib/python3.6/site-packages/sqlalchemy/sql/elements.py", line 269, in _execute_on_connection
    return connection._execute_clauseelement(self, multiparams, params)
  File "/Users/zhaochenxi/.local/share/virtualenvs/snack-api-lin-g_CxUc26/lib/python3.6/site-packages/sqlalchemy/engine/base.py", line 1060, in _execute_clauseelement
    compiled_sql, distilled_params
  File "/Users/zhaochenxi/.local/share/virtualenvs/snack-api-lin-g_CxUc26/lib/python3.6/site-packages/sqlalchemy/engine/base.py", line 1200, in _execute_context
    context)
  File "/Users/zhaochenxi/.local/share/virtualenvs/snack-api-lin-g_CxUc26/lib/python3.6/site-packages/sqlalchemy/engine/base.py", line 1413, in _handle_dbapi_exception
    exc_info
  File "/Users/zhaochenxi/.local/share/virtualenvs/snack-api-lin-g_CxUc26/lib/python3.6/site-packages/sqlalchemy/util/compat.py", line 265, in raise_from_cause
    reraise(type(exception), exception, tb=exc_tb, cause=cause)
  File "/Users/zhaochenxi/.local/share/virtualenvs/snack-api-lin-g_CxUc26/lib/python3.6/site-packages/sqlalchemy/util/compat.py", line 248, in reraise
    raise value.with_traceback(tb)
  File "/Users/zhaochenxi/.local/share/virtualenvs/snack-api-lin-g_CxUc26/lib/python3.6/site-packages/sqlalchemy/engine/base.py", line 1193, in _execute_context
    context)
  File "/Users/zhaochenxi/.local/share/virtualenvs/snack-api-lin-g_CxUc26/lib/python3.6/site-packages/sqlalchemy/engine/default.py", line 509, in do_execute
    cursor.execute(statement, parameters)
  File "/Users/zhaochenxi/.local/share/virtualenvs/snack-api-lin-g_CxUc26/lib/python3.6/site-packages/cymysql/cursors.py", line 135, in execute
    self.errorhandler(exc, value)
  File "/Users/zhaochenxi/.local/share/virtualenvs/snack-api-lin-g_CxUc26/lib/python3.6/site-packages/cymysql/cursors.py", line 37, in errorhandler
    self.connection.errorhandler(self, errorclass, errorvalue)
  File "/Users/zhaochenxi/.local/share/virtualenvs/snack-api-lin-g_CxUc26/lib/python3.6/site-packages/cymysql/connections.py", line 117, in errorhandler
    raise errorvalue
  File "/Users/zhaochenxi/.local/share/virtualenvs/snack-api-lin-g_CxUc26/lib/python3.6/site-packages/cymysql/cursors.py", line 130, in execute
    self._query(query)
  File "/Users/zhaochenxi/.local/share/virtualenvs/snack-api-lin-g_CxUc26/lib/python3.6/site-packages/cymysql/cursors.py", line 240, in _query
    conn.query(q)
  File "/Users/zhaochenxi/.local/share/virtualenvs/snack-api-lin-g_CxUc26/lib/python3.6/site-packages/cymysql/connections.py", line 346, in query
    self._result = MySQLResult(self)
  File "/Users/zhaochenxi/.local/share/virtualenvs/snack-api-lin-g_CxUc26/lib/python3.6/site-packages/cymysql/packet.py", line 270, in __init__
    self.first_packet = MysqlPacket(self.connection)
  File "/Users/zhaochenxi/.local/share/virtualenvs/snack-api-lin-g_CxUc26/lib/python3.6/site-packages/cymysql/packet.py", line 66, in __init__
    raise_mysql_exception(self.__data)
  File "/Users/zhaochenxi/.local/share/virtualenvs/snack-api-lin-g_CxUc26/lib/python3.6/site-packages/cymysql/err.py", line 149, in raise_mysql_exception
    _check_mysql_exception(errinfo)
  File "/Users/zhaochenxi/.local/share/virtualenvs/snack-api-lin-g_CxUc26/lib/python3.6/site-packages/cymysql/err.py", line 141, in _check_mysql_exception
    raise errorclass(errno, errorvalue)
sqlalchemy.exc.IntegrityError: (cymysql.err.IntegrityError) (1048, "Column 'price' cannot be null") [SQL: 'INSERT INTO product (create_time, update_time, delete_time, name, price, stock, summary, category_id, theme_id, img_id) VALUES (%s, %s, %s, %s, %s, %s, %s, %s, %s, %s)'] [parameters: (datetime.datetime(2019, 11, 16, 23, 51, 57, 74088), datetime.datetime(2019, 11, 16, 23, 51, 57, 74129), None, '芹菜1', None, 0, '芹菜好吃吗', 1, 1, 2)] (Background on this error at: http://sqlalche.me/e/gkpj)

2019-11-16 23:51:57,111 DEBUG 82714   ---  [MainThread] - [POST] -> [/cms/product] from:127.0.0.1 costs:8097.220 ms data:{
	param: {}, 
	body: {'category_id': 1, 'img_id': 2, 'name': '芹菜1', 'price_str': '1.012', 'stock': 0, 'summary': '芹菜好吃吗', 'theme_id': 1}
} 
2019-11-16 23:52:46,816 DEBUG 82743   ---  [MainThread] - [GET] -> [/cms/product/3] from:127.0.0.1 costs:30.080 ms data:{
	param: {}, 
	body: {}
} 
2019-11-16 23:52:47,262 DEBUG 82743   ---  [MainThread] - [GET] -> [/cms/product/paginate] from:127.0.0.1 costs:54.870 ms data:{
	param: {}, 
	body: {}
} 
2019-11-16 23:54:25,512 ERROR 82743   ---  [MainThread] - Traceback (most recent call last):
  File "/Users/zhaochenxi/.local/share/virtualenvs/snack-api-lin-g_CxUc26/lib/python3.6/site-packages/sqlalchemy/engine/base.py", line 1193, in _execute_context
    context)
  File "/Users/zhaochenxi/.local/share/virtualenvs/snack-api-lin-g_CxUc26/lib/python3.6/site-packages/sqlalchemy/engine/default.py", line 509, in do_execute
    cursor.execute(statement, parameters)
  File "/Users/zhaochenxi/.local/share/virtualenvs/snack-api-lin-g_CxUc26/lib/python3.6/site-packages/cymysql/cursors.py", line 135, in execute
    self.errorhandler(exc, value)
  File "/Users/zhaochenxi/.local/share/virtualenvs/snack-api-lin-g_CxUc26/lib/python3.6/site-packages/cymysql/cursors.py", line 37, in errorhandler
    self.connection.errorhandler(self, errorclass, errorvalue)
  File "/Users/zhaochenxi/.local/share/virtualenvs/snack-api-lin-g_CxUc26/lib/python3.6/site-packages/cymysql/connections.py", line 117, in errorhandler
    raise errorvalue
  File "/Users/zhaochenxi/.local/share/virtualenvs/snack-api-lin-g_CxUc26/lib/python3.6/site-packages/cymysql/cursors.py", line 130, in execute
    self._query(query)
  File "/Users/zhaochenxi/.local/share/virtualenvs/snack-api-lin-g_CxUc26/lib/python3.6/site-packages/cymysql/cursors.py", line 240, in _query
    conn.query(q)
  File "/Users/zhaochenxi/.local/share/virtualenvs/snack-api-lin-g_CxUc26/lib/python3.6/site-packages/cymysql/connections.py", line 346, in query
    self._result = MySQLResult(self)
  File "/Users/zhaochenxi/.local/share/virtualenvs/snack-api-lin-g_CxUc26/lib/python3.6/site-packages/cymysql/packet.py", line 270, in __init__
    self.first_packet = MysqlPacket(self.connection)
  File "/Users/zhaochenxi/.local/share/virtualenvs/snack-api-lin-g_CxUc26/lib/python3.6/site-packages/cymysql/packet.py", line 66, in __init__
    raise_mysql_exception(self.__data)
  File "/Users/zhaochenxi/.local/share/virtualenvs/snack-api-lin-g_CxUc26/lib/python3.6/site-packages/cymysql/err.py", line 149, in raise_mysql_exception
    _check_mysql_exception(errinfo)
  File "/Users/zhaochenxi/.local/share/virtualenvs/snack-api-lin-g_CxUc26/lib/python3.6/site-packages/cymysql/err.py", line 141, in _check_mysql_exception
    raise errorclass(errno, errorvalue)
cymysql.err.IntegrityError: (1048, "Column 'price' cannot be null")

The above exception was the direct cause of the following exception:

Traceback (most recent call last):
  File "/Users/zhaochenxi/.local/share/virtualenvs/snack-api-lin-g_CxUc26/lib/python3.6/site-packages/flask/app.py", line 1813, in full_dispatch_request
    rv = self.dispatch_request()
  File "/Users/zhaochenxi/.local/share/virtualenvs/snack-api-lin-g_CxUc26/lib/python3.6/site-packages/flask/app.py", line 1799, in dispatch_request
    return self.view_functions[rule.endpoint](**req.view_args)
  File "/Users/zhaochenxi/Home/PythonProjects/flask-api/snack-api-lin/app/api/cms/product.py", line 51, in create
    Product.add_model(form.data, err_msg='相关商品已存在')
  File "/Users/zhaochenxi/Home/PythonProjects/flask-api/snack-api-lin/app/models/base.py", line 167, in add_model
    cls.create(**data, commit=True)
  File "/Users/zhaochenxi/.local/share/virtualenvs/snack-api-lin-g_CxUc26/lib/python3.6/site-packages/lin/interface.py", line 149, in create
    db.session.commit()
  File "/Users/zhaochenxi/.local/share/virtualenvs/snack-api-lin-g_CxUc26/lib/python3.6/site-packages/sqlalchemy/orm/scoping.py", line 153, in do
    return getattr(self.registry(), name)(*args, **kwargs)
  File "/Users/zhaochenxi/.local/share/virtualenvs/snack-api-lin-g_CxUc26/lib/python3.6/site-packages/sqlalchemy/orm/session.py", line 943, in commit
    self.transaction.commit()
  File "/Users/zhaochenxi/.local/share/virtualenvs/snack-api-lin-g_CxUc26/lib/python3.6/site-packages/sqlalchemy/orm/session.py", line 467, in commit
    self._prepare_impl()
  File "/Users/zhaochenxi/.local/share/virtualenvs/snack-api-lin-g_CxUc26/lib/python3.6/site-packages/sqlalchemy/orm/session.py", line 447, in _prepare_impl
    self.session.flush()
  File "/Users/zhaochenxi/.local/share/virtualenvs/snack-api-lin-g_CxUc26/lib/python3.6/site-packages/sqlalchemy/orm/session.py", line 2254, in flush
    self._flush(objects)
  File "/Users/zhaochenxi/.local/share/virtualenvs/snack-api-lin-g_CxUc26/lib/python3.6/site-packages/sqlalchemy/orm/session.py", line 2380, in _flush
    transaction.rollback(_capture_exception=True)
  File "/Users/zhaochenxi/.local/share/virtualenvs/snack-api-lin-g_CxUc26/lib/python3.6/site-packages/sqlalchemy/util/langhelpers.py", line 66, in __exit__
    compat.reraise(exc_type, exc_value, exc_tb)
  File "/Users/zhaochenxi/.local/share/virtualenvs/snack-api-lin-g_CxUc26/lib/python3.6/site-packages/sqlalchemy/util/compat.py", line 249, in reraise
    raise value
  File "/Users/zhaochenxi/.local/share/virtualenvs/snack-api-lin-g_CxUc26/lib/python3.6/site-packages/sqlalchemy/orm/session.py", line 2344, in _flush
    flush_context.execute()
  File "/Users/zhaochenxi/.local/share/virtualenvs/snack-api-lin-g_CxUc26/lib/python3.6/site-packages/sqlalchemy/orm/unitofwork.py", line 391, in execute
    rec.execute(self)
  File "/Users/zhaochenxi/.local/share/virtualenvs/snack-api-lin-g_CxUc26/lib/python3.6/site-packages/sqlalchemy/orm/unitofwork.py", line 556, in execute
    uow
  File "/Users/zhaochenxi/.local/share/virtualenvs/snack-api-lin-g_CxUc26/lib/python3.6/site-packages/sqlalchemy/orm/persistence.py", line 181, in save_obj
    mapper, table, insert)
  File "/Users/zhaochenxi/.local/share/virtualenvs/snack-api-lin-g_CxUc26/lib/python3.6/site-packages/sqlalchemy/orm/persistence.py", line 866, in _emit_insert_statements
    execute(statement, params)
  File "/Users/zhaochenxi/.local/share/virtualenvs/snack-api-lin-g_CxUc26/lib/python3.6/site-packages/sqlalchemy/engine/base.py", line 948, in execute
    return meth(self, multiparams, params)
  File "/Users/zhaochenxi/.local/share/virtualenvs/snack-api-lin-g_CxUc26/lib/python3.6/site-packages/sqlalchemy/sql/elements.py", line 269, in _execute_on_connection
    return connection._execute_clauseelement(self, multiparams, params)
  File "/Users/zhaochenxi/.local/share/virtualenvs/snack-api-lin-g_CxUc26/lib/python3.6/site-packages/sqlalchemy/engine/base.py", line 1060, in _execute_clauseelement
    compiled_sql, distilled_params
  File "/Users/zhaochenxi/.local/share/virtualenvs/snack-api-lin-g_CxUc26/lib/python3.6/site-packages/sqlalchemy/engine/base.py", line 1200, in _execute_context
    context)
  File "/Users/zhaochenxi/.local/share/virtualenvs/snack-api-lin-g_CxUc26/lib/python3.6/site-packages/sqlalchemy/engine/base.py", line 1413, in _handle_dbapi_exception
    exc_info
  File "/Users/zhaochenxi/.local/share/virtualenvs/snack-api-lin-g_CxUc26/lib/python3.6/site-packages/sqlalchemy/util/compat.py", line 265, in raise_from_cause
    reraise(type(exception), exception, tb=exc_tb, cause=cause)
  File "/Users/zhaochenxi/.local/share/virtualenvs/snack-api-lin-g_CxUc26/lib/python3.6/site-packages/sqlalchemy/util/compat.py", line 248, in reraise
    raise value.with_traceback(tb)
  File "/Users/zhaochenxi/.local/share/virtualenvs/snack-api-lin-g_CxUc26/lib/python3.6/site-packages/sqlalchemy/engine/base.py", line 1193, in _execute_context
    context)
  File "/Users/zhaochenxi/.local/share/virtualenvs/snack-api-lin-g_CxUc26/lib/python3.6/site-packages/sqlalchemy/engine/default.py", line 509, in do_execute
    cursor.execute(statement, parameters)
  File "/Users/zhaochenxi/.local/share/virtualenvs/snack-api-lin-g_CxUc26/lib/python3.6/site-packages/cymysql/cursors.py", line 135, in execute
    self.errorhandler(exc, value)
  File "/Users/zhaochenxi/.local/share/virtualenvs/snack-api-lin-g_CxUc26/lib/python3.6/site-packages/cymysql/cursors.py", line 37, in errorhandler
    self.connection.errorhandler(self, errorclass, errorvalue)
  File "/Users/zhaochenxi/.local/share/virtualenvs/snack-api-lin-g_CxUc26/lib/python3.6/site-packages/cymysql/connections.py", line 117, in errorhandler
    raise errorvalue
  File "/Users/zhaochenxi/.local/share/virtualenvs/snack-api-lin-g_CxUc26/lib/python3.6/site-packages/cymysql/cursors.py", line 130, in execute
    self._query(query)
  File "/Users/zhaochenxi/.local/share/virtualenvs/snack-api-lin-g_CxUc26/lib/python3.6/site-packages/cymysql/cursors.py", line 240, in _query
    conn.query(q)
  File "/Users/zhaochenxi/.local/share/virtualenvs/snack-api-lin-g_CxUc26/lib/python3.6/site-packages/cymysql/connections.py", line 346, in query
    self._result = MySQLResult(self)
  File "/Users/zhaochenxi/.local/share/virtualenvs/snack-api-lin-g_CxUc26/lib/python3.6/site-packages/cymysql/packet.py", line 270, in __init__
    self.first_packet = MysqlPacket(self.connection)
  File "/Users/zhaochenxi/.local/share/virtualenvs/snack-api-lin-g_CxUc26/lib/python3.6/site-packages/cymysql/packet.py", line 66, in __init__
    raise_mysql_exception(self.__data)
  File "/Users/zhaochenxi/.local/share/virtualenvs/snack-api-lin-g_CxUc26/lib/python3.6/site-packages/cymysql/err.py", line 149, in raise_mysql_exception
    _check_mysql_exception(errinfo)
  File "/Users/zhaochenxi/.local/share/virtualenvs/snack-api-lin-g_CxUc26/lib/python3.6/site-packages/cymysql/err.py", line 141, in _check_mysql_exception
    raise errorclass(errno, errorvalue)
sqlalchemy.exc.IntegrityError: (cymysql.err.IntegrityError) (1048, "Column 'price' cannot be null") [SQL: 'INSERT INTO product (create_time, update_time, delete_time, name, price, stock, summary, category_id, theme_id, img_id) VALUES (%s, %s, %s, %s, %s, %s, %s, %s, %s, %s)'] [parameters: (datetime.datetime(2019, 11, 16, 23, 53, 31, 731123), datetime.datetime(2019, 11, 16, 23, 53, 31, 731174), None, '芹菜1', None, 0, '芹菜好吃吗', 1, 1, 2)] (Background on this error at: http://sqlalche.me/e/gkpj)

2019-11-16 23:54:26,052 DEBUG 82743   ---  [MainThread] - [POST] -> [/cms/product] from:127.0.0.1 costs:98759.380 ms data:{
	param: {}, 
	body: {'category_id': 1, 'img_id': 2, 'name': '芹菜1', 'price_str': '1.012', 'stock': 0, 'summary': '芹菜好吃吗', 'theme_id': 1}
} 
2019-11-16 23:59:01,044 DEBUG 82838   ---  [MainThread] - [GET] -> [/cms/product/3] from:127.0.0.1 costs:29.670 ms data:{
	param: {}, 
	body: {}
} 
2019-11-16 23:59:01,420 DEBUG 82838   ---  [MainThread] - [GET] -> [/cms/product/paginate] from:127.0.0.1 costs:37.730 ms data:{
	param: {}, 
	body: {}
} 
2019-11-16 23:59:03,689 DEBUG 82838   ---  [MainThread] - [POST] -> [/cms/product] from:127.0.0.1 costs:2241.830 ms data:{
	param: {}, 
	body: {'category_id': 1, 'img_id': 2, 'name': '芹菜1', 'price_str': '1.012', 'stock': 0, 'summary': '芹菜好吃吗', 'theme_id': 1}
} 
